[TOC]

## 取消与超时

* 这一部分包含了协程的取消与超时。

### 一、取消协程的执行

* 在一个长时间运行的应用程序中，你也许需要对你的后台协程进行细粒度的控制。 比如说，一个用户也许关闭了一个启动了协程的界面，那么现在协程的执行结果已经不再被需要了，这时，它应该是可以被取消的。 该 [launch](https://kotlin.github.io/kotlinx.coroutines/kotlinx-coroutines-core/kotlinx.coroutines/launch.html) 函数返回了一个可以被用来取消运行中的协程的 [Job](https://kotlin.github.io/kotlinx.coroutines/kotlinx-coroutines-core/kotlinx.coroutines/-job/index.html)：

```kotlin
fun main() = runBlocking {
    val job = launch {
        repeat(1000) { i ->
            println("job: I'm sleeping $i ...")
            delay(500L)
        }
    }
    delay(1300L) // 延迟一段时间
    println("main: I'm tired of waiting!")
    job.cancel() // 取消该作业
    job.join() // 等待作业执行结束
    println("main: Now I can quit.")
}
```

* 程序执行后的输出如下：

```
job: I'm sleeping 0 ...
job: I'm sleeping 1 ...
job: I'm sleeping 2 ...
main: I'm tired of waiting!
main: Now I can quit.
```

* 一旦 main 函数调用了 `job.cancel`，我们在其它的协程中就看不到任何输出，因为它被取消了。 这里也有一个可以使 [Job](https://kotlin.github.io/kotlinx.coroutines/kotlinx-coroutines-core/kotlinx.coroutines/-job/index.html) 挂起的函数 [cancelAndJoin](https://kotlin.github.io/kotlinx.coroutines/kotlinx-coroutines-core/kotlinx.coroutines/cancel-and-join.html) 它合并了对 [cancel](https://kotlin.github.io/kotlinx.coroutines/kotlinx-coroutines-core/kotlinx.coroutines/-job/cancel.html) 以及 [join](https://kotlin.github.io/kotlinx.coroutines/kotlinx-coroutines-core/kotlinx.coroutines/-job/join.html) 的调用。

### 二、取消是协作的

* 协程的取消是 *协作* 的。一段协程代码必须协作才能被取消。 所有 `kotlinx.coroutines` 中的挂起函数都是 *可被取消的* 。它们检查协程的取消， 并在取消时抛出 [CancellationException](https://kotlin.github.io/kotlinx.coroutines/kotlinx-coroutines-core/kotlinx.coroutines/-cancellation-exception/index.html)。 然而，如果协程正在执行计算任务，并且没有检查取消的话，那么它是不能被取消的，就如如下示例代码所示：

```kotlin
fun main() = runBlocking {
    val startTime = System.currentTimeMillis()
    val job = launch(Dispatchers.Default) {
        var nextPrintTime = startTime
        var i = 0
        while (i < 5) { // 一个执行计算的循环，只是为了占用 CPU
            // 每秒打印消息两次
            if (System.currentTimeMillis() >= nextPrintTime) {
                println("job: I'm sleeping ${i++} ...")
                nextPrintTime += 500L
            }
        }
    }
    delay(1300L) // 等待一段时间
    println("main: I'm tired of waiting!")
    job.cancelAndJoin() // 取消一个作业并且等待它结束
    println("main: Now I can quit.")
}
```

* 运行示例代码，并且我们可以看到它连续打印出了“I'm sleeping”，甚至在调用取消后， 作业仍然执行了五次循环迭代并运行到了它结束为止。
* 输出结果

```
job: I'm sleeping 0 ...
job: I'm sleeping 1 ...
job: I'm sleeping 2 ...
main: I'm tired of waiting!
job: I'm sleeping 3 ...
job: I'm sleeping 4 ...
main: Now I can quit.
```

### 三、使计算代码可取消

* 我们有两种方法来使执行计算的代码可以被取消。第一种方法是定期调用挂起函数来检查取消。对于这种目的 [yield](https://kotlin.github.io/kotlinx.coroutines/kotlinx-coroutines-core/kotlinx.coroutines/yield.html) 是一个好的选择。 另一种方法是显式的检查取消状态。让我们试试第二种方法。

* 将前一个示例中的 `while (i < 5)` 替换为 `while (isActive)` 并重新运行它。

```kotlin
fun main() = runBlocking {
    val startTime = System.currentTimeMillis()
    val job = launch(Dispatchers.Default) {
        var nextPrintTime = startTime
        var i = 0
        while (isActive) { // 可以被取消的计算循环
            // 每秒打印消息两次
            if (System.currentTimeMillis() >= nextPrintTime) {
                println("job: I'm sleeping ${i++} ...")
                nextPrintTime += 500L
            }
        }
    }
    delay(1300L) // 等待一段时间
    println("main: I'm tired of waiting!")
    job.cancelAndJoin() // 取消该作业并等待它结束
    println("main: Now I can quit.")
}
```

* 输出结果

```
job: I'm sleeping 0 ...
job: I'm sleeping 1 ...
job: I'm sleeping 2 ...
main: I'm tired of waiting!
main: Now I can quit.
```

* 你可以看到，现在循环被取消了。[isActive](https://kotlin.github.io/kotlinx.coroutines/kotlinx-coroutines-core/kotlinx.coroutines/is-active.html) 是一个可以被使用在 [CoroutineScope](https://kotlin.github.io/kotlinx.coroutines/kotlinx-coroutines-core/kotlinx.coroutines/-coroutine-scope/index.html) 中的扩展属性。

### 四、在 `finally` 中释放资源

* 我们通常使用如下的方法处理在被取消时抛出 [CancellationException](https://kotlin.github.io/kotlinx.coroutines/kotlinx-coroutines-core/kotlinx.coroutines/-cancellation-exception/index.html) 的可被取消的挂起函数。比如说，`try {……} finally {……}` 表达式以及 Kotlin 的 `use` 函数一般在协程被取消的时候执行它们的终结动作：

```kotlin
fun main() = runBlocking {
    val job = launch {
        try {
            repeat(1000) { i ->
                println("job: I'm sleeping $i ...")
                delay(500L)
            }
        } finally {
            println("job: I'm running finally")
        }
    }
    delay(1300L) // delay a bit
    println("main: I'm tired of waiting!")
    job.cancelAndJoin() // cancels the job and waits for its completion
    println("main: Now I can quit.")    
}
```

* [join](https://kotlin.github.io/kotlinx.coroutines/kotlinx-coroutines-core/kotlinx.coroutines/-job/join.html) 和 [cancelAndJoin](https://kotlin.github.io/kotlinx.coroutines/kotlinx-coroutines-core/kotlinx.coroutines/cancel-and-join.html) 等待了所有的终结动作执行完毕， 所以运行示例得到了下面的输出：

```
job: I'm sleeping 0 ...
job: I'm sleeping 1 ...
job: I'm sleeping 2 ...
main: I'm tired of waiting!
job: I'm running finally
main: Now I can quit.
```

### 五、运行不能取消的代码块

* 在前一个例子中任何尝试在 `finally` 块中调用挂起函数的行为都会抛出 [CancellationException](https://kotlin.github.io/kotlinx.coroutines/kotlinx-coroutines-core/kotlinx.coroutines/-cancellation-exception/index.html)，因为这里持续运行的代码是可以被取消的。通常，这并不是一个问题，所有良好的关闭操作（关闭一个文件、取消一个作业、或是关闭任何一种通信通道）通常都是非阻塞的，并且不会调用任何挂起函数。然而，在真实的案例中，当你需要挂起一个被取消的协程，你可以将相应的代码包装在 `withContext(NonCancellable) {……}` 中，并使用 [withContext](https://kotlin.github.io/kotlinx.coroutines/kotlinx-coroutines-core/kotlinx.coroutines/with-context.html) 函数以及 [NonCancellable](https://kotlin.github.io/kotlinx.coroutines/kotlinx-coroutines-core/kotlinx.coroutines/-non-cancellable.html) 上下文，见如下示例所示：

```kotlin
fun main() = runBlocking {
    val job = launch {
        try {
            repeat(1000) { i ->
                println("job: I'm sleeping $i ...")
                delay(500L)
            }
        } finally {
            withContext(NonCancellable) {
                println("job: I'm running finally")
                delay(1000L)
                println("job: And I've just delayed for 1 sec because I'm non-cancellable")
            }
        }
    }
    delay(1300L) // delay a bit
    println("main: I'm tired of waiting!")
    job.cancelAndJoin() // cancels the job and waits for its completion
    println("main: Now I can quit.")    
}
```

* 输出结果

```
job: I'm sleeping 0 ...
job: I'm sleeping 1 ...
job: I'm sleeping 2 ...
main: I'm tired of waiting!
job: I'm running finally
job: And I've just delayed for 1 sec because I'm non-cancellable
main: Now I can quit.
```

* 如果不用 withContext(NonCancellable)的化，输出结果将不一样

```kotlin
fun main() = runBlocking {
    val job = launch {
        try {
            repeat(1000) { i ->
                println("job: I'm sleeping $i ...")
                delay(500L)
            }
        } finally {
            println("job: I'm running finally")
            delay(1000L)
            println("job: And I've just delayed for 1 sec because I'm non-cancellable")
        }
    }
    delay(1300L) // delay a bit
    println("main: I'm tired of waiting!")
    job.cancelAndJoin() // cancels the job and waits for its completion
    println("main: Now I can quit.")
}
```

* 输出结果

```
job: I'm sleeping 0 ...
job: I'm sleeping 1 ...
job: I'm sleeping 2 ...
main: I'm tired of waiting!
job: I'm running finally
main: Now I can quit.
```

### 六、超时

* 在实践中绝大多数取消一个协程的理由是它有可能超时。 当你手动追踪一个相关 [Job](https://kotlin.github.io/kotlinx.coroutines/kotlinx-coroutines-core/kotlinx.coroutines/-job/index.html) 的引用并启动了一个单独的协程在延迟后取消追踪，这里已经准备好使用 [withTimeout](https://kotlin.github.io/kotlinx.coroutines/kotlinx-coroutines-core/kotlinx.coroutines/with-timeout.html) 函数来做这件事。 来看看示例代码：

```kotlin
fun main() = runBlocking {
    withTimeout(1300L) {
        repeat(1000) { i ->
            println("I'm sleeping $i ...")
            delay(500L)
        }
    }
}
```

* 运行后得到如下输出：

```
I'm sleeping 0 ...
I'm sleeping 1 ...
I'm sleeping 2 ...
Exception in thread "main" kotlinx.coroutines.TimeoutCancellationException: Timed out waiting for 1300 ms
```

* [withTimeout](https://kotlin.github.io/kotlinx.coroutines/kotlinx-coroutines-core/kotlinx.coroutines/with-timeout.html) 抛出了 `TimeoutCancellationException`，它是 [CancellationException](https://kotlin.github.io/kotlinx.coroutines/kotlinx-coroutines-core/kotlinx.coroutines/-cancellation-exception/index.html) 的子类。 我们之前没有在控制台上看到堆栈跟踪信息的打印。这是因为在被取消的协程中 `CancellationException` 被认为是协程执行结束的正常原因。 然而，在这个示例中我们在 `main` 函数中正确地使用了 `withTimeout`。

* 由于取消只是一个例外，所有的资源都使用常用的方法来关闭。 如果你需要做一些各类使用超时的特别的额外操作，可以使用类似 [withTimeout](https://kotlin.github.io/kotlinx.coroutines/kotlinx-coroutines-core/kotlinx.coroutines/with-timeout.html) 的 [withTimeoutOrNull](https://kotlin.github.io/kotlinx.coroutines/kotlinx-coroutines-core/kotlinx.coroutines/with-timeout-or-null.html) 函数，并把这些会超时的代码包装在 `try {...} catch (e: TimeoutCancellationException) {...}` 代码块中，而 [withTimeoutOrNull](https://kotlin.github.io/kotlinx.coroutines/kotlinx-coroutines-core/kotlinx.coroutines/with-timeout-or-null.html) 通过返回 `null` 来进行超时操作，从而替代抛出一个异常：

```kotlin
fun main() = runBlocking {
    val result = withTimeoutOrNull(1300L) {
        repeat(1000) { i ->
            println("I'm sleeping $i ...")
            delay(500L)
        }
        "Done" // 在它运行得到结果之前取消它
    }
    println("Result is $result")
}
```

* 运行这段代码时不再抛出异常：

```
I'm sleeping 0 ...
I'm sleeping 1 ...
I'm sleeping 2 ...
Result is null
```

### 七、异步超时和资源

* The timeout event in [withTimeout](https://kotlin.github.io/kotlinx.coroutines/kotlinx-coroutines-core/kotlinx.coroutines/with-timeout.html) is asynchronous with respect to the code running in its block and may happen at any time, even right before the return from inside of the timeout block. Keep this in mind if you open or acquire some resource inside the block that needs closing or release outside of the block.
* [withTimeout 中](https://kotlin.github.io/kotlinx.coroutines/kotlinx-coroutines-core/kotlinx.coroutines/with-timeout.html)的超时事件与其块中代码运行都是异步的，并且随时会发生。甚至在从超时事件块内部返回之前。如果您在块内打开或获取某些需要在块外关闭或释放的资源，请注意这一点。

* For example, here we imitate a closeable resource with the `Resource` class, that simply keeps track of how many times it was created by incrementing the `acquired` counter and decrementing this counter from its `close` function. Let us run a lot of coroutines with the small timeout try acquire this resource from inside of the `withTimeout` block after a bit of delay and release it from outside.
* 例如，这里我们用`Resource`类模拟了一个可关闭的资源，它通过增加`acquired`计数器并从其`close`函数中减少这个`acquired`计数器来简单地跟踪它被创建的次数。然后重复很多次进行小时间的`withTimeout`， 尝试`withTimeout`在延迟一段时间后从块内部获取此资源并从外部释放它。

```kotlin
var acquired = 0

class Resource {
    init { acquired++ } // Acquire the resource
    fun close() { acquired-- } // Release the resource
}

fun main() {
    runBlocking {
        repeat(100_000) { // Launch 100K coroutines
            launch { 
                val resource = withTimeout(60) { // Timeout of 60 ms
                    delay(50) // Delay for 50 ms
                    Resource() // Acquire a resource and return it from withTimeout block     
                }
                resource.close() // Release the resource
            }
        }
    }
    // Outside of runBlocking all coroutines have completed
    println(acquired) // Print the number of resources still acquired
}
```

* If you run the above code you'll see that it does not always print zero, though it may depend on the timings of your machine you may need to tweak timeouts in this example to actually see non-zero values.
* 如果你运行上面的代码，你会看到它并不总是打印零，尽管它可能取决于你机器的时间，你可能需要在这个例子中调整超时以实际看到非零值。

> Note, that incrementing and decrementing `acquired` counter here from 100K coroutines is completely safe, since it always happens from the same main thread. More on that will be explained in the next chapter on coroutine context.
>
> 请注意，`acquired`此处从 100K 协程递增和递减计数器是完全安全的，因为它总是发生在同一个主线程中。更多相关内容将在下一章协程上下文中解释。

* To workaround this problem you can store a reference to the resource in the variable as opposed to returning it from the `withTimeout` block.
* 要解决此问题，您可以在变量中存储对资源的引用，而不是从`withTimeout`块中返回它。

```kotlin
var acquired = 0

class Resource {
    init { acquired++ } // Acquire the resource
    fun close() { acquired-- } // Release the resource
}

fun main() {
    runBlocking {
        repeat(100_000) { // Launch 100K coroutines
            launch { 
                var resource: Resource? = null // Not acquired yet
                try {
                    withTimeout(60) { // Timeout of 60 ms
                        delay(50) // Delay for 50 ms
                        resource = Resource() // Store a resource to the variable if acquired      
                    }
                    // We can do something else with the resource here
                } finally {  
                    resource?.close() // Release the resource if it was acquired
                }
            }
        }
    }
    // Outside of runBlocking all coroutines have completed
    println(acquired) // Print the number of resources still acquired
}
```

* This example always prints zero. Resources do not leak.
* 此示例始终打印零。资源不泄露。